<?xml version="1.0"?>
<robot xmlns:xacro="http://www.ros.org/wiki/xacro" name="ridar">

    <!-- include macros (생략 가능. 사용자 파일에 맞게) -->
    <xacro:include filename="macros.xacro"/>

    <!-- materials -->
    <material name='red'><color rgba="1 0 0 1"/></material>
    <material name="white"><color rgba="1 1 1 1"/></material>
    <material name="blue"><color rgba="0 0 1 1"/></material>
    <material name="black"><color rgba="0 0 0 1"/></material>

    <!-- base_link -->
    <link name="base_link"/>

    <!-- body -->
    <joint name="body_joint" type="fixed">
        <parent link="base_link"/>
        <child link="body"/>
        <origin xyz="-0.12 0 0"/>
    </joint>

    <link name="body">
        <visual>
            <origin xyz="0.1 0 0.03"/>
            <geometry><box size="0.2 0.1 0.06"/></geometry>
            <material name="white"/>
        </visual>
        <collision>
            <origin xyz="0.1 0 0.03"/>
            <geometry><box size="0.2 0.1 0.06"/></geometry>
        </collision>
        <xacro:inertial_box mass="0.5" x="0.2" y="0.1" z="0.06">
            <origin xyz="0.1 0 0.03" rpy="0 0 0"/>
        </xacro:inertial_box>
    </link>

    <!-- left wheel -->
    <joint name="left_wheel_joint" type="continuous">
        <parent link="base_link"/>
        <child link="left_wheel"/>
        <origin xyz="0 0.065 0" rpy="-${pi/2} 0 0" />
        <axis xyz="0 0 1"/>
    </joint>

    <link name="left_wheel">
        <visual>
            <geometry><cylinder radius="0.03" length="0.03"/></geometry>
            <material name="blue"/>
        </visual>
        <collision>
            <geometry><cylinder radius="0.03" length="0.03"/></geometry>
        </collision>
        <xacro:inertial_cylinder mass="0.1" length="0.03" radius="0.03">
            <origin xyz="0 0 0" rpy="0 0 0"/>
        </xacro:inertial_cylinder>
    </link>

    <!-- right wheel -->
    <joint name="right_wheel_joint" type="continuous">
        <parent link="base_link"/>
        <child link="right_wheel"/>
        <origin xyz="0 -0.065 0" rpy="${pi/2} 0 0" />
        <axis xyz="0 0 -1"/>
    </joint>

    <link name="right_wheel">
        <visual>
            <geometry><cylinder radius="0.03" length="0.03"/></geometry>
            <material name="blue"/>
        </visual>
        <collision>
            <geometry><cylinder radius="0.03" length="0.03"/></geometry>
        </collision>
        <xacro:inertial_cylinder mass="0.1" length="0.03" radius="0.03">
            <origin xyz="0 0 0" rpy="0 0 0"/>
        </xacro:inertial_cylinder>
    </link>

    <!-- caster wheel -->
    <joint name="caster_wheel_joint" type="fixed">
        <parent link="body"/>
        <child link="caster_wheel"/>
        <origin xyz="0.03 0 0"/>
    </joint>

    <link name="caster_wheel">
        <visual>
            <geometry><sphere radius="0.03"/></geometry>
            <material name="black"/>
        </visual>
        <collision>
            <geometry><sphere radius="0.03"/></geometry>
        </collision>
        <xacro:inertial_sphere mass="0.1" radius="0.03">
            <origin xyz="0 0 0" rpy="0 0 0"/>
        </xacro:inertial_sphere>
    </link>

    <!-- LiDAR -->
    <joint name="laser_joint" type="fixed">
        <parent link="body"/>
        <child link="laser_frame"/>
        <origin xyz="0.1 0 0.075" rpy="0 0 0"/>
    </joint>

    <link name="laser_frame">
        <visual>
            <geometry><cylinder radius="0.03" length="0.03"/></geometry>
            <material name="red"/>
        </visual>
        <collision>
            <geometry><cylinder radius="0.03" length="0.03"/></geometry>
        </collision>
    </link>

    <!-- include lidar xacro (사용자 필요 시) -->
    <xacro:include filename="lidar.xacro"/>
    <xacro:include filename="gazebo.xacro"/>

</robot>
